Workbook
Name Precio_climaTech: 'Unidad económica'!$B$7
Name CantidadGrupos: 'Caso de negocio (anual) '!$C$6
Name Precio_regular: 'Unidad económica'!$B$6
Name TC_USD_ARS: Horas.Esfuerzo.Facilitacion!$G$1

Sheet Caso de negocio (anual) 
A1: CASO DE NEGOCIO - CÍRCULOS CLIMATECH
A2: Programa de antifragilidad financiera para startups climate tech
A4: INGRESOS
A5: Concepto | B5: Detalle | C5: Monto USD | D5: %
A6: Cantidad de grupos | B6: 4 grupos de 10 personas | C6: 4
A7: Suscripciones de Startups | B7: 40 founders en el año 1 | C7: ='Unidad económica'!E15*CantidadGrupos -> 200640 | D7: =C7/C10 -> 0.88920404
A8: Grant capital semilla | B8: Inicial | C8: 25000 | D8: =C8/C10 -> 0.11079596
A10: TOTAL INGRESOS | C10: =SUM(C7:C8) -> 225640 | D10: =SUM(D7:D8) -> 1
A12: EGRESOS
A13: Categoría | B13: Detalle | C13: Monto USD | D13: %
A14: Honorarios facilitación | B14: 50% de ingresos (8 facilitadores para 4 grupos) | C14: ='Unidad económica'!E18*CantidadGrupos -> 100320 | D14: =C14/$C$24 -> 0.58557086
A15: Eventos de adquisición | B15: 16 eventos × $825 (4 pde 50p x Q) | C15: ='Unidad económica'!E19*CantidadGrupos -> 13200 | D15: =C15/$C$24 -> 0.077048798
A16: Marketing y research | B16: responsable de difusion y eventos | C16: ='Unidad económica'!E20*CantidadGrupos -> 33900 | D16: =C16/$C$24 -> 0.19787532
A17: DETALLE MARKETING (ver hoja "Estrategias Marketing")
A18: Base anterior | B18: Reducido (facilitadores impulsan) | C18: 5000 | D18: =C18/$C$24 -> 0.029185151
A19: + Historias con Impacto | C19: 11400 | D19: =C19/$C$24 -> 0.066542143
A20: + Mini Research Hub | C20: 2500 | D20: =C20/$C$24 -> 0.014592575
A21: Gastos logísticos | C21: ='Unidad económica'!E24*CantidadGrupos -> 5000 | D21: =C21/$C$24 -> 0.029185151
A22: Imprevistos | C22: ='Unidad económica'!E25*CantidadGrupos -> 4000 | D22: =C22/$C$24 -> 0.02334812
A24: TOTAL EGRESOS | C24: =SUM(C14:C21) -> 171320 | D24: =SUM(D14:D21) -> 1
A26: BALANCE (I-E) | C26: =C10-C24 -> 54320
A28: DISTRIBUCIÓN SOCIOS (50/50)
A29: Fondo Aliados Locales (50%) | C29: =C26*0.5 -> 27160
A30: Fondo Equipo Estratégico (50%) | C30: =C26*0.5 -> 27160

Sheet Unidad económica
A1: CÍRCULOS CLIMATECH - UNIT ECONOMICS POR GRUPO
A2: Análisis de unidad mínima viable (1 grupo de 10 founders)
A4: INPUTS - GRUPO ESTÁNDAR | D4: INGRESOS ANUALES - 1 GRUPO
A5: Founders por grupo | B5: =SUM(E5:E8) -> 10 | D5: Founders regulares (No base cientifica-tech) | E5: 2
A6: Precio mensual (regular) | B6: 500 | D6: Founders ClimaTech | E6: 3
A7: Precio mensual (ClimaTech 20% menos) | B7: =B6*(1-B8) -> 400 | D7: Founders anual (No base cientifica-tech) | E7: 2
A8: % bonificacion ClimaTech | B8: 0.2 | D8: Founders anual ClimaTech | E8: 3
A9: % bonificacion anual | B9: 0.1
A10: % bonificacion anual ClimaTech | B10: 0.3 | D10: Revenue mensual regulares | E10: =E5*B6 -> 1000
A11: Precio trimestral (regular) | B11: =Precio_regular*3 -> 1500 | D11: Revenue mensual ClimaTech | E11: =E6*B7 -> 1200
A12: Precio trimestral (ClimaTech) | B12: =Precio_climaTech*3 -> 1200 | D12: Revenue mensual regulares (pago anual) | E12: =Precio_regular*E7*(1-B9) -> 900
A13: Precio anual (regular) | B13: =Precio_regular*12*(1-B9) -> 5400 | D13: Revenue mensual ClimaTech (pago anual) | E13: =Precio_climaTech*E8*(1-B9) -> 1080
A14: Precio anual (ClimaTech acumulado 30% menos) | B14: =Precio_climaTech*12*(1-B9) -> 4320 | D14: MRR por grupo | E14: =E10+E11+E12+E13 -> 4180
D15: ARR por grupo (aprox) | E15: =E14*12 -> 50160
A16: Facilitadores por grupo | B16: 2
A17: % revenue share facilitadores | B17: 0.5 | D17: EGRESOS ANUALES - 1 GRUPO
D18: Facilitadores (50% revenue) | E18: =E15*B17 -> 25080 | H18: =E18/$E$27 -> 0.53813968
A19: Eventos adquisición/trimestre | B19: 4 | D19: Eventos adquisición (prorata) | E19: =(B19*4*B20)/4 -> 3300 | F19: Asume 4 grupos | H19: =E19/$E$27 -> 0.070807853
A20: Costo por evento | B20: ='Presupuesto Eventos'!D7 -> 825 | D20: Marketing (prorata) | E20: 8475 | F20: Base $5k + Historias $2850 + Research $625 | H20: =E20/$E$27 -> 0.18184744
A21: Asistentes por evento | B21: ='Presupuesto Eventos'!D11 -> 50 | D21: Gestión comercial (prorata) | E21: 4000 | H21: =E21/$E$27 -> 0.085827701
A22: Conv eventos → leads (%) | B22: ='Presupuesto Eventos'!B17 -> 0.5 | D22: Operativa (prorata) | E22: =6000/4 -> 1500 | H22: =E22/$E$27 -> 0.032185388
A23: Cantidad de Leads (trimestral) | B23: =B19*B21*B22 -> 100 | D23: Tech/oficina (prorata) | E23: 2000 | H23: =E23/$E$27 -> 0.04291385
A24: Conv leads → clientes (%) | B24: ='Presupuesto Eventos'!B19 -> 0.1 | D24: Logística (prorata) | E24: =5000/4 -> 1250 | H24: =E24/$E$27 -> 0.026821157
A25: Cantidad de Clientes (trimestral) | B25: =B23*B24 -> 10 | D25: Imprevistos (prorata) | E25: =4000/4 -> 1000 | H25: =E25/$E$27 -> 0.021456925
A27: UNIT ECONOMICS | D27: Total Egresos | E27: =SUM(E18:E25) -> 46605
A28: LTV (12 meses) | B28: =E14*12 -> 50160
A29: CAC por cliente | B29: =(E19+E20+E21)/B5 -> 1577.5 | D29: BALANCE POR GRUPO
A30: LTV:CAC ratio | B30: =B28/B29 -> 31.797147 | D30: ARR neto | E30: =E15 -> 50160
A31: Payback period (meses) | B31: =B29/E14 -> 0.37739234 | D31: Total Egresos | E31: =E27 -> 46605
D32: Balance Neto | E32: =E30-E31 -> 3555
A33: Clientes por evento | B33: =B5/(B19*4) -> 0.625
A34: CAC por evento | B34: =B20/(B21*B22*B24) -> 330 | D34: Margen Bruto | E34: =(E30-E18)/E30 -> 0.5
D35: Margen Neto | E35: =E32/E30 -> 0.070873206

Sheet Resumen Mkt
A1: RESUMEN EJECUTIVO - ESTRATEGIA DE MKT
A2: Círculos Impacto+ | Enero 2026
A4: 1. ESTRATEGIAS COMPLEMENTARIAS
B5: Estrategia | C5: Costo Anual | D5: Leads/Año | E5: Clientes/Año | F5: Descripción
A6: A | B6: Almuerzos Networking | C6: $0 | D6: 27 | E6: 3 | F6: Autofinanciados, 1/mes, 5 a 7 personas
A7: B | B7: Historias con Impacto | C7: $11,400 | D7: 40 | E7: 4 | F7: Research + storytelling, unidad on-demand
A8: C | B8: Mini Research Hub | C8: $2,500 | D8: 15 | E8: 1-2 | F8: Policy briefs ClimaTech
B9: TOTAL NUEVAS | C9: $13,900 | D9: 82 | E9: 8-9 | F9: Complementa los 4 eventos trimestrales
A11: 2. ANÁLISIS COMPARATIVO (por grupo)
A12: Métrica | B12: Baseline | C12: Con Nuevas | D12: Variación | E12: % Cambio | F12: Comentario
A13: Marketing por grupo | B13: $5,000 | C13: $8,475 | D13: +$3,475 | E13: +69.5% | F13: Mayor alcance por $ invertido
A14: Marketing anual (4 grupos) | B14: $20,000 | C14: $33,900 | D14: +$13,900 | E14: +69.5%
A15: Leads totales/año | B15: 300 | C15: 382 | D15: +82 | E15: +27.3% | F15: Diversificación de fuentes
A16: Clientes totales/año | B16: 30 | C16: 38-39 | D16: +8-9 | E16: +27%
A17: CAC (Costo/Cliente) | B17: $440 | C17: $186 | D17: -$254 | E17: -57.7% | F17: 🎯 Mejora significativa
A18: ROI (Revenue/Costo) | B18: 9.6x | C18: 18.2x | D18: +8.6x | E18: +89.6% | F18: 🎯 Casi duplica rentabilidad
A19: 3. PLAN DE IMPLEMENTACIÓN
A20: Fase | B20: Timing | C20: Inversión | D20: Acciones Clave | E20: KPIs | F20: Status
A21: Setup | B21: Mes 1-2 | C21: $1,900 | D21: Contratar equipo Primer almuerzo Primera historia | E21: >12 asistentes 1 historia | F21: 🔵 Iniciar
A22: Validación | B22: Mes 3-6 | C22: $3,800 | D22: 3 historias 3 almuerzos Medir engagement | E22: CTR >5% 3 leads/mes | F22: ⚪ Pendiente
A23: Scale | B23: Mes 7-12 | C23: $8,200 | D23: Policy brief Webinar 6 almuerzos | E23: 200 descargas 30 asistentes | F23: ⚪ Pendiente
A25: 4. RECOMENDACIÓN Y PRÓXIMOS PASOS
A26: ✅ RECOMENDACIÓN: REFINAR E IMPLEMENTAR
A27: • Diversificar fuentes de leads: reduce dependencia de eventos presenciales
A28: • Construye autoridad de marca a mediano plazo (research + contenido)
A29: • Modelo escalable: prorrateo de costos compartidos entre grupos
A31: 🎯 PRÓXIMOS PASOS INMEDIATOS (Semana 1-2):
A32: 1. Verificar "capital semilla" para presupuesto estrategias de atracción: $13,900/año
A33: 2. Contratar horas de equipo on-demand: researcher + content writer
A34: 3. Agendar primer almuerzo networking (10 invitados)
A35: 4. Definir primea ronda de 3 "Historia con Impacto"
A37: 📊 MÉTRICAS A SEGUIR (primeros 90 días):
A38: • Asistencia almuerzos: >5 founders/almuerzo
... A40: • Leads inbound: >2/mes

Sheet Estrategias Marketing
A1: ESTRATEGIAS DE ATRACCIÓN Y CONVERSIÓN DE LEADS
A2: Programa Círculos Impacto+ (actualizado)
A4: ESTRATEGIA ACTUAL (Baseline)
A5: Concepto | B5: Frecuencia/Cantidad | C5: Costo Unitario | D5: Costo Anual | E5: Leads/Año | F5: Clientes/Año
A6: Eventos presenciales | B6: 16 eventos/año | C6: 825 | D6: =C6*16 -> 13200 | E6: 300 | F6: 30
A7: Marketing y research base | B7: Anual | C7: 5000 | D7: 5000 | E7: - | F7: -
A8: TOTAL ACTUAL | D8: =D6+D7 -> 18200 | E8: =E6 -> 300 | F8: =F6 -> 30
A10: NUEVAS ESTRATEGIAS DE MARKETING (Propuesta)
A11: Estrategia | B11: Recursos | C11: Costo Mensual | D11: Costo Anual | E11: Leads Est./Año | F11: Clientes Est./Año | G11: Notas
A12: 1. Almuerzos Networking | B12: Autofinanciado por asistentes | C12: 0 | D12: 0 | E12: 27 | F12: 3 | G12: 1/mes, 15 personas, conv 15%→10%
A13: Coordinación | B13: 2h/mes rol equipo del día a día | C13: 0 | D13: 0 | G13: Sin costo adicional
A14: Venue | B14: Restaurante (consumo 70KARS/persona) | C14: 0 | D14: 0 | G14: Sin costo operativo
A16: 2. Historias con Impacto | B16: Research + storytelling | C16: 950 | D16: =C16*12 -> 11400 | E16: 40 | F16: 5 | G16: Unidad on-demand
A17: Researcher junior | B17: 20h/mes × $25/h | C17: 500 | D17: =C17*12 -> 6000 | G17: Freelance
A18: Content writer | B18: 15h/mes × $30/h | C18: 450 | D18: =C18*12 -> 5400 | G18: Periodista freelance
A19: Entregables | B19: 12 casos + 4 briefs/año | G19: 36 piezas contenido
A21: 3. Mini Research Hub | B21: Autoridad temática | D21: 2500 | E21: 15 | F21: 2 | G21: Estilo Civic Compass
A22: Policy brief anual | B22: 1 investigación/año | D22: 2500 | G22: Co-branded con universidades
A23: Webinars divulgación | B23: 2 eventos/año × 30 asist | D23: 0 | G23: Incluido en costo research
A25: TOTAL NUEVAS ESTRATEGIAS | D25: =D16+D21 -> 13900 | E25: =E12+E16+E21 -> 82 | F25: =F12+F16+F21 -> 10
A28: ANÁLISIS COMPARATIVO
A29: Concepto | B29: Baseline | C29: Con Nuevas | D29: Variación | E29: % Cambio
A30: Inversión Marketing por Grupo | B30: 5000 | C30: 8475 | D30: =C30-B30 -> 3475 | E30: =D30/B30 -> 0.695
A31: Inversión Marketing Anual (4 grupos) | B31: =B30*4 -> 20000 | C31: =C30*4 -> 33900 | D31: =C31-B31 -> 13900 | E31: =D31/B31 -> 0.695
A32: Leads Totales/Año | B32: =E8 -> 300 | C32: =E8+E25 -> 382 | D32: =C32-B32 -> 82 | E32: =D32/B32 -> 0.27333333
A33: Clientes Totales/Año | B33: =F8 -> 30 | C33: =F8+F25 -> 40 | D33: =C33-B33 -> 10 | E33: =D33/B33 -> 0.33333333
A34: Costo por Lead | B34: =B30/B32 -> 16.666667 | C34: =C30/C32 -> 22.185864 | D34: =C34-B34 -> 5.5191972 | E34: =D34/B34 -> 0.33115183
A35: Costo por Cliente (CAC) | B35: =B30/B33 -> 166.66667 | C35: =C30/C33 -> 211.875 | D35: =C35-B35 -> 45.208333 | E35: =D35/B35 -> 0.27125
A36: ROI (Revenue/Costo) | B36: ='Unidad económica'!E15*B33/B30 -> 300.96 | C36: ='Unidad económica'!E15*C33/C30 -> 236.74336 | D36: =C36-B36 -> -64.216637 | E36: =D36/B36 -> -0.21337266
A38: TIMELINE DE IMPLEMENTACIÓN
A39: Fase | B39: Periodo | C39: Acciones | D39: Inversión | E39: Hitos Clave
A40: SETUP | B40: Mes 1-2 | C40: Contratar researcher + writer Crear templates historias Lanzar 1er almuerzo | D40: $1,900 | E40: 15 asistentes almuerzo 1 historia publicada
A41: VALIDACIÓN | B41: Mes 3-6 | C41: Publicar 3 historias Medir engagement 3 almuerzos más | D41: $3,800 | E41: CTR >5% 3+ leads inbound/mes 45 contactos totales
A42: ESCALAMIENTO | B42: Mes 7-12 | C42: Policy brief 1 webinar 6 almuerzos | D42: $8,200 | E42: 1 research publicado 30 asistentes webinar 90 contactos almuerzo
A44: KPIS Y MÉTRICAS
A45: Categoría | B45: KPI | C45: Target Mes 3 | D45: Target Mes 6 | E45: Target Año 1
A46: Almuerzos | B46: Asistencia promedio | C46: >12 | D46: >15 | E46: >15
B47: Leads generados | C47: 8 | D47: 15 | E47: 27
A48: Historias | B48: CTR LinkedIn | C48: >3% | D48: >5% | E48: >7%
B49: Shares por post | C49: >10 | D49: >15 | E49: >20
...

Sheet CashFlow 60m
A1: CÍRCULOS CLIMATECH - CASH FLOW 60 MESES
A2: Apertura por grupos completos (10 founders/grupo)
A4: ASSUMPTIONS
A5: Founders/grupo | B5: 10
A6: MRR/grupo | B6: ='Unidad económica'!E14 -> 4180
A7: Grant inicial | B7: 25000
A8: Churn grupos (anual Y2-5) | B8: 0.05
A10: CALENDARIO
A11: Año 1: M1, M7, M9, M11 (4 grupos = 40 founders)
A12: Año 2: +6 grupos (total 10 grupos = 100 founders)
A13: Año 3: +6 grupos (total 16 grupos = 160 founders)
A14: Año 4: +5 grupos (total 21 grupos = 210 founders)
A15: Año 5: +4 grupos (total 25 grupos = 250 founders)
A18: CONCEPTO | B18: M1 | C18: M2 | D18: M3 | E18: M4 | F18: M5 | G18: M6 | H18: M7 | I18: M8 | J18: M9 | K18: M10 | L18: M11 | M18: M12 | N18: Q1Y2 | O18: Q2Y2 | P18: Q3Y2 | Q18: Q4Y2 | R18: Q1Y3 | S18: Q2Y3 | T18: Q3Y3 | U18: Q4Y3 | V18: Q1Y4 | W18: Q2Y4 | X18: Q3Y4 | Y18: Q4Y4 | Z18: Q1Y5 | AA18: Q2Y5 | AB18: Q3Y5 | AC18: Q4Y5
A19: Grupos inicio | B19: 0 | C19: 1 | D19: 1 | E19: 1 | F19: 1 | G19: 1 | H19: 1 | I19: 2 | J19: 2 | K19: 3 | L19: 3 | M19: 4 | N19: 4 | O19: 5.95 | P19: 7.875625 | Q19: 8.7771797 | R19: 9.6674649 | S19: 11.546622 | T19: 13.402289 | U19: 14.23476 | V19: 15.056826 | W19: 16.868615 | X19: 17.657758 | Y19: 18.437036 | Z19: 19.206573 | AA19: 19.966491 | AB19: 20.71691 | AC19: 21.457948
A20: Nuevos grupos | B20: 1 | C20: 0 | D20: 0 | E20: 0 | F20: 0 | G20: 0 | H20: 1 | I20: 0 | J20: 1 | K20: 0 | L20: 1 | M20: 0 | N20: 2 | O20: 2 | P20: 1 | Q20: 1 | R20: 2 | S20: 2 | T20: 1 | U20: 1 | V20: 2 | W20: 1 | X20: 1 | Y20: 1 | Z20: 1 | AA20: 1 | AB20: 1 | AC20: 1
A21: Grupos fin | B21: 1 | C21: 1 | D21: 1 | E21: 1 | F21: 1 | G21: 1 | H21: 2 | I21: 2 | J21: 3 | K21: 3 | L21: 4 | M21: 4 | N21: 5.95 | O21: 7.875625 | P21: 8.7771797 | Q21: 9.6674649 | R21: 11.546622 | S21: 13.402289 | T21: 14.23476 | U21: 15.056826 | V21: 16.868615 | W21: 17.657758 | X21: 18.437036 | Y21: 19.206573 | Z21: 19.966491 | AA21: 20.71691 | AB21: 21.457948 | AC21: 22.189724
A23: MRR | B23: 3344 | C23: 3344 | D23: 3344 | E23: 3344 | F23: 3344 | G23: 3344 | H23: 6688 | I23: 6688 | J23: 10032 | K23: 10032 | L23: 13376 | M23: 13376 | N23: 49909.2 | O23: 69349.335 | P23: 83530.468 | Q23: 92518.337 | R23: 106409.86 | S23: 125143.74 | T23: 138627.44 | U23: 146926.6 | V23: 160138.01 | W23: 173184.29 | X23: 181051.48 | Y23: 188820.34 | Z23: 196492.09 | AA23: 204067.94 | AB23: 211549.09 | AC23: 218936.72
A24: Grant | B24: =B7 -> 25000 | C24: 0 | D24: 0 | E24: 0 | F24: 0 | G24: 0 | H24: 0 | I24: 0 | J24: 0 | K24: 0 | L24: 0 | M24: 0 | N24: 0 | O24: 0 | P24: 0 | Q24: 0 | R24: 0 | S24: 0 | T24: 0 | U24: 0 | V24: 0 | W24: 0 | X24: 0 | Y24: 0 | Z24: 0 | AA24: 0 | AB24: 0 | AC24: 0
A25: Total Ingresos | B25: =SUM(B23:B24) -> 28344 | C25: =SUM(C23:C24) -> 3344 | D25: =SUM(D23:D24) -> 3344 | E25: =SUM(E23:E24) -> 3344 | F25: =SUM(F23:F24) -> 3344 | G25: =SUM(G23:G24) -> 3344 | H25: =SUM(H23:H24) -> 6688 | I25: =SUM(I23:I24) -> 6688 | ... AC25: =SUM(AC23:AC24) -> 218936.72
A27: Facilitadores | B27: 1672 | C27: 1672 | D27: 1672 | E27: 1672 | F27: 1672 | G27: 1672 | H27: 3344 | I27: 3344 | J27: 5016 | K27: 5016 | L27: 6688 | M27: 6688 | N27: 24954.6 | O27: 34674.668 | P27: 41765.234 | Q27: 46259.169 | R27: 53204.929 | S27: 62571.868 | T27: 69313.719 | U27: 73463.298 | V27: 80069.006 | W27: 86592.144 | X27: 90525.742 | Y27: 94410.17 | Z27: 98246.043 | AA27: 102033.97 | AB27: 105774.54 | AC27: 109468.36
A28: Otros egresos | B28: =1004.16666666667 -> 1004.1667 | C28: 1004.1667 | D28: 1004.1667 | E28: 1004.1667 | F28: 1004.1667 | G28: 1004.1667 | H28: 2008.3333 | I28: 2008.3333 | J28: 3012.5 | K28: 3012.5 | L28: 4016.6667 | M28: 4016.6667 | N28: 14987.188 | O28: 20824.848 | P28: 25083.287 | Q28: 27782.246 | R28: 31953.718 | S28: 37579.296 | T28: 41628.305 | U28: 44120.451 | V28: 48087.696 | W28: 52005.35 | X28: 54367.783 | Y28: 56700.685 | Z28: 59004.427 | AA28: 61279.372 | AB28: 63525.879 | AC28: 65744.306
A29: Total Egresos | B29: =SUM(B27:B28) -> 2676.1667 | C29: =SUM(C27:C28) -> 2676.1667 | D29: =SUM(D27:D28) -> 2676.1667 | E29: =SUM(E27:E28) -> 2676.1667 | F29: =SUM(F27:F28) -> 2676.1667 | G29: =SUM(G27:G28) -> 2676.1667 | H29: =SUM(H27:H28) -> 5352.3333 | I29: =SUM(I27:I28) -> 5352.3333 | ... AC29: =SUM(AC27:AC28) -> 175212.67
A31: Cash Flow (I-E) | B31: =B25-B29 -> 25667.833 | C31: =C25-C29 -> 667.83333 | D31: =D25-D29 -> 667.83333 | E31: =E25-E29 -> 667.83333 | F31: =F25-F29 -> 667.83333 | G31: =G25-G29 -> 667.83333 | H31: =H25-H29 -> 1335.6667 | I31: =I25-I29 -> 1335.6667 | ... AC31: =AC25-AC29 -> 43724.055
A32: Saldo Acumulado | B32: 25667.833 | C32: =B32+C31 -> 26335.667 | D32: =C32+D31 -> 27003.5 | E32: =D32+E31 -> 27671.333 | F32: =E32+F31 -> 28339.167 | G32: =F32+G31 -> 29007 | H32: =G32+H31 -> 30342.667 | I32: =H32+I31 -> 31678.333 | J32: =I32+J31 -> 33681.833 | ... AC32: =AB32+AC31 -> 509680.63

Sheet Objetivos
A1: OBJETIVOS POR ETAPA DEL FUNNEL
A3: Etapa | B3: Indicador | C3: Objetivo Trimestral | D3: Objetivo Mensual
A4: Atracción visitantes | B4: Asistentes a eventos informativos | C4: 200 founders | D4: 4 eventos de 50 founders
A5: Atracción visitantes | B5: Visitantes landing page | C5: 5,000 visitantes | D5: 1,667 visitantes
A6: Adquisición leads | B6: Leads calificados totales | C6: 30-35 leads | D6: 10-12 leads
A7: Adquisición leads | B7: Tasa conversión eventos → leads | C7: 0.5
A8: Conversión clientes | B8: Suscriptores activos (pagando) | C8: 9-10 clientes | D8: -
A9: Conversión clientes | B9: Tasa conversión leads → clientes | C9: 0.1
A10: Conversión clientes | B10: Lead time promedio | C10: 21 días | D10: -
A11: Profundización | B11: Tasa de retención mensual (churn) | C11: <5% | D11: <5%
A12: Profundización | B12: NPS (Net Promoter Score) | C12: ≥75 | D12: -
A13: Referidos | B13: % participantes que refieren | C13: 40% | D13: -
A14: Referidos | B14: Nuevos leads por referidos | C14: 3-4 por trimestre | D14: 1-2

Sheet Datos
A1: DATOS DEL PROGRAMA
A3: MODELO DE PRECIOS
A4: Categoría | B4: Precio Mensual | C4: Precio Anual
A5: Regular (mensual) | B5: $500 | C5: $6,000
A6: Regular (anual con 10% desc) | B6: $450 equiv | C6: $5,400
A7: ClimaTech (mensual con 10% desc) | B7: $450 | C7: $5,400
A8: ClimaTech (anual con 20% desc) | B8: $400 equiv | C8: $4,800
A10: ESTRUCTURA DEL PROGRAMA
A11: Concepto | B11: Descripción
A12: Tamaño de grupo | B12: 10-12 participantes por grupo
A13: Facilitadores por grupo | B13: 2 facilitadores senior
A14: Encuentros presenciales | B14: 4 por año (1 por trimestre)
A15: Sesiones 1:1 | B15: 4 por año (1 por trimestre)
A16: Onboarding | B16: 2 horas individual
A17: Duración membresía | B17: Trimestral mínima
A18: Meta año 1 | B18: 4 grupos = 36-44 clientes

Sheet Presupuesto Eventos
A1: PRESUPUESTO EVENTOS DE ADQUISICIÓN
A3: DETALLE POR EVENTO (50 personas)
A4: Concepto | B4: Cantidad | C4: Precio Unit | D4: Total USD
A5: Catering | B5: 50 | C5: 12.5 | D5: =B5*C5 -> 625
A6: Logística y materiales | B6: 1 | C6: 200 | D6: =B6*C6 -> 200
A7: TOTAL POR EVENTO | D7: =SUM(D5:D6) -> 825
A9: PROYECCIÓN ANUAL
A10: Eventos por trimestre | D10: 4
A11: Cantidad participantes por evento | D11: 50
A12: Total eventos año | D12: =D10*4 -> 16
A13: Asistentes totales año | D13: =D12*D11 -> 800
A14: PRESUPUESTO TOTAL ANUAL | D14: =D7*D12 -> 13200
A17: Conv eventos → leads (%) | B17: 0.5
A18: Cantidad de Leads (anual) | B18: =D13*B17 -> 400
A19: Conv leads → clientes (%) | B19: 0.1
A20: Cantidad de Clientes (5% de la participacion anual) | B20: =B18*B19 -> 40

Sheet Horas.Esfuerzo.Facilitacion
A1: Dimensión | B1: USD | C1: Pesos | F1: TC | G1: 1500
A2: Consultoria | B2: 250 | C2: =B2*$G$1 -> 375000
A3: Facilitación | B3: 150 | C3: =B3*$G$1 -> 225000
A4: Sesiones 1:1 | B4: 200 | C4: =B4*$G$1 -> 300000
A8: Eje | B8: Actividades trimestrales | C8: Horas | D8: Repeticiones | E8: Cant. de facilitadores | F8: Total (USD) | G8: Total ($)
A9: 1 | B9: RESEARCH + REFINAMIENTO
B10: Founder #1: clarificar y preparar "desafios" | C10: 3 | D10: 2 | E10: 1 | F10: =G10/TC_USD_ARS -> 1500 | G10: =C10*D10*E10*$C$2 -> 2250000 | H10: =F10/$F$21 -> 0.25
B11: Founder #2: clarificar y preparar "desafios" | C11: 3 | D11: 2 | E11: 1 | F11: =G11/TC_USD_ARS -> 1500 | G11: =C11*D11*E11*$C$2 -> 2250000 | H11: =F11/$F$21 -> 0.25
A13: 2 | B13: SESIONES GRUPALES
B14: Startup #1: Encuentro aprendizaje entre partes / cosecha aprendizajes | C14: 4 | D14: 1 | E14: 2 | F14: =G14/TC_USD_ARS -> 1200 | G14: =C14*D14*E14*$C$3 -> 1800000 | H14: =F14/$F$21 -> 0.2
B15: Startup #1: Encuentro aprendizaje entre partes / cosecha aprendizajes | C15: 4 | D15: 1 | E15: 2 | F15: =G15/TC_USD_ARS -> 1200 | G15: =C15*D15*E15*$C$3 -> 1800000 | H15: =F15/$F$21 -> 0.2
A17: 3 | B17: SESIONES INDIVIDUALES
B18: Encuentros 1:1 para trabajar plan de mejora individual | C18: 1 | D18: 3 | E18: 1 | F18: =G18/G1 -> 600 | G18: =C18*D18*E18*$C$4 -> 900000 | H18: =F18/F21 -> 0.1
E21: trimestral | F21: =SUM(F10:F19) -> 6000 | G21: =SUM(G10:G19) -> 9000000
E22: mensual (min 1k usd) | F22: =F21/3 -> 2000
E23: anual | F23: =F21*4 -> 24000
